package com.gingo.netty.demo11.fp;

import io.netty.channel.DefaultEventLoop;
import io.netty.util.concurrent.DefaultPromise;
import lombok.extern.slf4j.Slf4j;

import java.util.concurrent.ExecutionException;

@Slf4j
public class TestNettyPromise3 {
    public static void main(String[] args) throws ExecutionException, InterruptedException {
        DefaultEventLoop eventExecutors = new DefaultEventLoop();
        DefaultPromise<Integer> promise = new DefaultPromise<>(eventExecutors);

        eventExecutors.execute(() -> {
            try {
                Thread.sleep(1000);
            } catch (InterruptedException e) {
                e.printStackTrace();
            }
            RuntimeException e = new RuntimeException("error...");
            log.debug("set failure, {}", e.toString());
            promise.setFailure(e);
        });

        log.debug("start...");
        log.debug("{}", promise.getNow());
        promise.get(); // sync() 也会出现异常，只是 get 会再用 ExecutionException 包一层异常
    }
}
